Workbook

Sheet Directory
A1: THE ₹100 DOLLAR QUESTION
A2: Research workbook | Does a falling rupee change which investments build wealth?
A4: Purpose | B4: Compare Indian equities, US equities measured in INR, gold and inflation over a common monthly period.
A5: Study window | B5: January 2016–September 2026 (monthly). Use the latest complete month available across all series.
A6: Important status | B6: This is a calculation-ready workbook template. The market-data input cells are intentionally blank until source series are downloaded and reconciled; no historical returns are invented.
A7: Step 1 | B7: Download monthly USD/INR from FRED (EXINUS). The series is a monthly average of daily rates, not a month-end rate.
A8: Step 2 | B8: Download monthly gold prices in USD/oz and INR/oz (or USD/gram and INR/gram) from the World Gold Council. Confirm units.
A9: Step 3 | B9: Download Nifty 50 TRI and S&P 500 total-return data. Do not compare a price-only index with a total-return index without clearly labelling the difference.
A10: Step 4 | B10: Download Indian CPI from MoSPI and use one consistent CPI series/base throughout.
A11: Step 5 | B11: Paste values into the matching raw-data columns in Monthly Data. Formulas calculate INR-converted US equity value, returns, growth of ₹1 lakh, drawdown and real value.
A12: Interpretation rule | B12: Currency conversion can increase or reduce INR returns. Historical performance does not establish that an asset will outperform in the future.
A13: Limitations | B13: The workbook does not yet include transaction costs, taxes, gold duties/premiums, fund expenses, tracking error or actual investor cash flows.
A16: Primary sources
A17: USD/INR monthly series — FRED EXINUS | B17: https://fred.stlouisfed.org/series/EXINUS
A18: Gold prices and downloadable historical averages — World Gold Council | B18: https://www.gold.org/goldhub/data/gold-prices
A19: Nifty Indices historical data | B19: https://www.niftyindices.com/reports/historical-data
A20: S&P 500 series portal — FRED (check index type; price index excludes dividends) | B20: https://fred.stlouisfed.org/series/SP500
A21: India CPI — MoSPI data catalogue | B21: https://esankhyiki.mospi.gov.in/catalogue-main/catalogue?product=CPI

Sheet Raw_Data
A1: NIFTY DAILY | H1: NIFTY MONTHLY | P1: S&P 500 | X1: GOLD INR | AG1: GOLD USD | AO1: Annexure-IV | AY1: Date | AZ1: Year | BA1: Month | BB1: Combined CPI Index (2024=100) | BC1: Rural CPI Index (2024=100) | BD1: Urban CPI Index (2024=100) | BE1: Combined YoY Inflation (%) | BF1: Rural YoY Inflation (%) | BG1: Urban YoY Inflation (%) | BI1: observation_date | BJ1: EXINUS
AQ2: All India Combined (General) level index and inflation | AY2: 42370 | AZ2: 2016 | BA2: 1 | BB2: 66.5 | BC2: 66.9 | BD2: 66.1 | BE2: 5.69 | BF2: 6.48 | BG2: 4.81 | BI2: 42370 | BJ2: 67.3332
A3: Date | B3: Price | C3: Open | D3: High | E3: Low | F3: Vol. | G3: Change % | I3: Date | J3: Price | K3: Open | L3: High | M3: Low | N3: Vol. | O3: Change % | Q3: Date | R3: Price | S3: Open | T3: High | U3: Low | V3: Vol. | W3: Change % | Z3: Date | AA3: Price | AB3: Open | AC3: High | AD3: Low | AE3: Vol. | AF3: Change % | AH3: Date | AI3: Price | AJ3: Open | AK3: High | AL3: Low | AM3: Vol. | AN3: Change % | AQ3: Month | AR3: Index | AU3: Inflation (%) | AY3: 42401 | AZ3: 2016 | BA3: 2 | BB3: 66.4 | BC3: 66.8 | BD3: 65.9 | BE3: 5.26 | BF3: 6.05 | BG3: 4.3 | BI3: 42401 | BJ3: 68.2395
A4: 42370 | B4: 7963.2 | C4: 7938.45 | D4: 7972.55 | E4: 7909.8 | F4: 64.84M | G4: 0.0021 | I4: 42370 | J4: 7563.55 | K4: 7938.45 | L4: 7972.55 | M4: 7241.5 | N4: 3.96B | O4: -0.0482 | Q4: 42370 | R4: 1940.24 | S4: 2038.2 | T4: 2038.2 | U4: 1812.29 | W4: -0.0507 | Z4: 42370 | AA4: 75852 | AB4: 70238 | AC4: 76914 | AD4: 70141 | AF4: 0.0807 | AH4: 42370 | AI4: 1117.64 | AJ4: 1061.09 | AK4: 1128.3 | AL4: 1060.74 | AN4: 0.0535 | AR4: Rural | AS4: Urban | AT4: Combined | AU4: Rural | AV4: Urban | AW4: Combined | AY4: 42430 | AZ4: 2016 | BA4: 3 | BB4: 66.4 | BC4: 66.8 | BD4: 65.9 | BE4: 4.83 | BF4: 5.7 | BG4: 3.95 | BI4: 42430 | BJ4: 66.8909
A5: 42373 | B5: 7791.3 | C5: 7924.55 | D5: 7937.55 | E5: 7781.1 | F5: 138.86M | G5: -0.0216 | I5: 42371 | J5: 6987.05 | K5: 7589.5 | L5: 7600.45 | M5: 6825.8 | N5: 5.33B | O5: -0.0762 | Q5: 42371 | R5: 1932.23 | S5: 1936.94 | T5: 1962.96 | U5: 1810.1 | W5: -0.0041 | Z5: 42371 | AA5: 84450 | AB5: 75890 | AC5: 86284 | AD5: 75782 | AF5: 0.1134 | AH5: 42371 | AI5: 1237.76 | AJ5: 1117.85 | AK5: 1261.17 | AL5: 1116.24 | AN5: 0.1075 | AQ5: (i) | AR5: (ii) | AS5: (iii) | AT5: (iv) | AU5: (v) | AV5: (vi) | AW5: (vii) | AY5: 42461 | AZ5: 2016 | BA5: 4 | BB5: 67 | BC5: 67.4 | BD5: 66.7 | BE5: 5.47 | BF5: 6.17 | BG5: 4.68 | BI5: 42461 | BJ5: 66.4219
A6: 42374 | B6: 7784.65 | C6: 7828.4 | D6: 7831.2 | E6: 7763.25 | F6: 149.67M | G6: -0.0009 | I6: 42372 | J6: 7738.4 | K6: 7038.25 | L6: 7777.6 | M6: 7035.1 | N6: 4.96B | O6: 0.1075 | Q6: 42372 | R6: 2059.74 | S6: 1937.09 | T6: 2072.21 | U6: 1937.09 | W6: 0.066 | Z6: 42372 | AA6: 81617 | AB6: 84490 | AC6: 86367 | AD6: 80843 | AF6: -0.0335 | AH6: 42372 | AI6: 1231.95 | AJ6: 1238.19 | AK6: 1282.9 | AL6: 1208.55 | AN6: -0.0047 | AQ6: Jan-25 | AR6: 101.81 | AS6: 101.49 | AT6: 101.67 | AY6: 42491 | AZ6: 2016 | BA6: 5 | BB6: 67.7 | BC6: 68 | BD6: 67.4 | BE6: 5.76 | BF6: 6.45 | BG6: 4.89 | BI6: 42491 | BJ6: 66.8895
A7: 42375 | B7: 7741 | C7: 7788.05 | D7: 7800.95 | E7: 7721.2 | F7: 151.72M | G7: -0.0056 | I7: 42373 | J7: 7849.8 | K7: 7718.05 | L7: 7992 | M7: 7516.85 | N7: 3.65B | O7: 0.0144 | Q7: 42373 | R7: 2065.3 | S7: 2056.62 | T7: 2111.05 | U7: 2033.8 | W7: 0.0027 | Z7: 42373 | AA7: 85898 | AB7: 81673 | AC7: 86036 | AD7: 80234 | AF7: 0.0525 | AH7: 42373 | AI7: 1293.36 | AJ7: 1232.7 | AK7: 1296.58 | AL7: 1209 | AN7: 0.0498 | AQ7: Feb-25 | AR7: 101.33 | AS7: 101.3 | AT7: 101.32 | AY7: 42522 | AZ7: 2016 | BA7: 6 | BB7: 68.5 | BC7: 68.9 | BD7: 68.1 | BE7: 5.77 | BF7: 6.29 | BG7: 5.26 | BI7: 42522 | BJ7: 67.2655
A8: 42376 | B8: 7568.3 | C8: 7673.35 | D8: 7674.95 | E8: 7556.6 | F8: 194.73M | G8: -0.0223 | I8: 42374 | J8: 8160.1 | K8: 7822.7 | L8: 8213.6 | M8: 7678.35 | N8: 4.50B | O8: 0.0395 | Q8: 42374 | R8: 2096.96 | S8: 2067.17 | T8: 2103.48 | U8: 2025.91 | W8: 0.0153 | Z8: 42374 | AA8: 81626 | AB8: 85932 | AC8: 86592 | AD8: 80470 | AF8: -0.0497 | AH8: 42374 | AI8: 1214.69 | AJ8: 1293.69 | AK8: 1303.97 | AL8: 1199.88 | AN8: -0.0608 | AQ8: Mar-25 | AR8: 101.34 | AS8: 101.47 | AT8: 101.39 | AY8: 42552 | AZ8: 2016 | BA8: 7 | BB8: 69.1 | BC8: 69.5 | BD8: 68.6 | BE8: 6.07 | BF8: 6.66 | BG8: 5.39 | BI8: 42552 | BJ8: 67.158
A9: 42377 | B9: 7601.35 | C9: 7611.65 | D9: 7634.1 | E9: 7581.05 | F9: 162.35M | G9: 0.0044 | I9: 42375 | J9: 8287.75 | K9: 8179.2 | L9: 8308.15 | M9: 7927.05 | N9: 4.32B | O9: 0.0156 | Q9: 42375 | R9: 2098.86 | S9: 2093.94 | T9: 2120.55 | U9: 1991.68 | W9: 0.0009 | Z9: 42375 | AA9: 89212 | AB9: 81673 | AC9: 92587 | AD9: 81184 | AF9: 0.0929 | AH9: 42375 | AI9: 1321.78 | AJ9: 1215.85 | AK9: 1358.47 | AL9: 1206.02 | AN9: 0.0882 | AQ9: Apr-25 | AR9: 101.49 | AS9: 101.71 | AT9: 101.58 | AY9: 42583 | AZ9: 2016 | BA9: 8 | BB9: 69.1 | BC9: 69.7 | BD9: 68.3 | BE9: 5.05 | BF9: 5.87 | BG9: 4.22 | BI9: 42583 | BJ9: 66.9035
A10: 42380 | B10: 7563.85 | C10: 7527.45 | D10: 7605.1 | E10: 7494.35 | F10: 194.84M | G10: -0.0049 | I10: 42376 | J10: 8638.5 | K10: 8313.05 | L10: 8674.7 | M10: 8287.55 | N10: 3.42B | O10: 0.0423 | Q10: 42376 | R10: 2173.6 | S10: 2099.34 | T10: 2177.09 | U10: 2074.02 | W10: 0.0356 | Z10: 42376 | AA10: 89974 | AB10: 89259 | AC10: 92860 | AD10: 88061 | AF10: 0.0086 | AH10: 42376 | AI10: 1350.59 | AJ10: 1323.4 | AK10: 1375.3 | AL10: 1310.8 | AN10: 0.0218 | AQ10: May-25 | AR10: 101.78 | AS10: 102.06 | AT10: 101.9 | AY10: 42614 | AZ10: 2016 | BA10: 9 | BB10: 68.9 | BC10: 69.7 | BD10: 68.1 | BE10: 4.39 | BF10: 5.04 | BG10: 3.64 | BI10: 42614 | BJ10: 66.7138
A11: 42381 | B11: 7510.3 | C11: 7587.2 | D11: 7588.3 | E11: 7487.8 | F11: 168.98M | G11: -0.0071 | I11: 42377 | J11: 8786.2 | K11: 8654.3 | L11: 8819.2 | M11: 8518.15 | N11: 4.22B | O11: 0.0171 | Q11: 42377 | R11: 2170.95 | S11: 2173.15 | T11: 2193.81 | U11: 2147.58 | W11: -0.0012 | Z11: 42377 | AA11: 87617 | AB11: 89982 | AC11: 91497 | AD11: 87419 | AF11: -0.0262 | AH11: 42377 | AI11: 1308.45 | AJ11: 1349.97 | AK11: 1367.69 | AL11: 1305.02 | AN11: -0.0312 | AQ11: Jun-25 | AR11: 102.39 | AS11: 102.66 | AT11: 102.51 | AY11: 42644 | AZ11: 2016 | BA11: 10 | BB11: 69.2 | BC11: 69.9 | BD11: 68.4 | BE11: 4.2 | BF11: 4.78 | BG11: 3.54 | BI11: 42644 | BJ11: 66.7415
A12: 42382 | B12: 7562.4 | C12: 7557.9 | D12: 7590.95 | E12: 7425.8 | F12: 221.91M | G12: 0.0069 | I12: 42378 | J12: 8611.15 | K12: 8793.6 | L12: 8968.7 | M12: 8555.2 | N12: 4.02B | O12: -0.0199 | Q12: 42378 | R12: 2168.27 | S12: 2171.33 | T12: 2187.87 | U12: 2119.12 | W12: -0.0012 | Z12: 42378 | AA12: 87561 | AB12: 87663 | AC12: 89808 | AD12: 87227 | AF12: -0.0006 | AH12: 42378 | AI12: 1315.8 | AJ12: 1309.35 | AK12: 1353.03 | AL12: 1302.33 | AN12: 0.0056 | AQ12: Jul-25 | AR12: 103.34 | AS12: 103.36 | AT12: 103.35 | AY12: 42675 | AZ12: 2016 | BA12: 11 | BB12: 69.1 | BC12: 69.8 | BD12: 68.4 | BE12: 3.63 | BF12: 4.13 | BG12: 3.13 | BI12: 42675 | BJ12: 67.6395
A13: 42383 | B13: 7536.8 | C13: 7467.4 | D13: 7604.8 | E13: 7443.8 | F13: 206.99M | G13: -0.0034 | I13: 42379 | J13: 8625.7 | K13: 8666.15 | L13: 8806.95 | M13: 8506.15 | N13: 3.42B | O13: 0.0017 | Q13: 42379 | R13: 2126.15 | S13: 2164.33 | T13: 2169.6 | U13: 2114.72 | W13: -0.0194 | Z13: 42379 | AA13: 85163 | AB13: 87584 | AC13: 87841 | AD13: 82681 | AF13: -0.0274 | AH13: 42379 | AI13: 1277.28 | AJ13: 1317.83 | AK13: 1319.93 | AL13: 1241.46 | AN13: -0.0293 | AQ13: Aug-25 | AR13: 103.84 | AS13: 103.6 | AT13: 103.74 | AY13: 42705 | AZ13: 2016 | BA13: 12 | BB13: 68.7 | BC13: 69.3 | BD13: 67.9 | BE13: 3.41 | BF13: 3.83 | BG13: 2.9 | BI13: 42705 | BJ13: 67.8052
A14: 42384 | B14: 7437.8 | C14: 7561.65 | D14: 7566.5 | E14: 7427.3 | F14: 203.64M | G14: -0.0131 | I14: 42380 | J14: 8224.5 | K14: 8653.15 | L14: 8669.6 | M14: 7916.4 | N14: 4.73B | O14: -0.0465 | Q14: 42380 | R14: 2198.81 | S14: 2128.68 | T14: 2214.1 | U14: 2083.79 | W14: 0.0342 | Z14: 42380 | AA14: 80464 | AB14: 85183 | AC14: 89489 | AD14: 80281 | AF14: -0.0552 | AH14: 42380 | AI14: 1172.7 | AJ14: 1276.9 | AK14: 1337.85 | AL14: 1170.72 | AN14: -0.0819 | AQ14: Sep-25 | AR14: 103.8 | AS14: 103.66 | AT14: 103.74 | AY14: 42736 | AZ14: 2017 | BA14: 1 | BB14: 68.6 | BC14: 69.1 | BD14: 68 | BE14: 3.17 | BF14: 3.36 | BG14: 2.9 | BI14: 42736 | BJ14: 68.0474
A15: 42387 | B15: 7351 | C15: 7420.35 | D15: 7463.65 | E15: 7336.4 | F15: 240.80M | G15: -0.0117 | I15: 42381 | J15: 8185.8 | K15: 8244 | L15: 8274.95 | M15: 7893.8 | N15: 3.22B | O15: -0.0047 | Q15: 42381 | R15: 2238.83 | S15: 2200.17 | T15: 2277.53 | U15: 2187.44 | W15: 0.0182 | Z15: 42381 | AA15: 78235 | AB15: 80488 | AC15: 80816 | AD15: 76234 | AF15: -0.0277 | AH15: 42381 | AI15: 1151.46 | AJ15: 1173.01 | AK15: 1188.09 | AL15: 1122.69 | AN15: -0.0181 | AQ15: Oct-25 | AR15: 103.85 | AS15: 103.61 | AT15: 103.74 | AY15: 42767 | AZ15: 2017 | BA15: 2 | BB15: 68.8 | BC15: 69.2 | BD15: 68.2 | BE15: 3.65 | BF15: 3.67 | BG15: 3.55 | BI15: 42767 | BJ15: 66.9726
A16: 42388 | B16: 7435.1 | C16: 7381.8 | D16: 7462.75 | E16: 7364.15 | F16: 194.07M | G16: 0.0114 | I16: 42736 | J16: 8561.3 | K16: 8210.1 | L16: 8672.7 | M16: 8133.8 | N16: 4.13B | O16: 0.0459 | Q16: 42736 | R16: 2278.87 | S16: 2251.57 | T16: 2300.99 | U16: 2245.13 | W16: 0.0179 | Z16: 42736 | AA16: 81660 | AB16: 78273 | AC16: 83052 | AD16: 78233 | AF16: 0.0438 | AH16: 42736 | AI16: 1210.51 | AJ16: 1151.09 | AK16: 1220.21 | AL16: 1145.99 | AN16: 0.0513 | AQ16: Nov-25 | AR16: 104.16 | AS16: 103.83 | AT16: 104.01 | AY16: 42795 | AZ16: 2017 | BA16: 3 | BB16: 68.9 | BC16: 69.3 | BD16: 68.5 | BE16: 3.89 | BF16: 3.75 | BG16: 3.96 | BI16: 42795 | BJ16: 65.8009
A17: 42389 | B17: 7309.3 | C17: 7357 | D17: 7470.9 | E17: 7241.5 | F17: 232.61M | G17: -0.0169 | I17: 42737 | J17: 8879.6 | K17: 8570.35 | L17: 8982.15 | M17: 8537.5 | N17: 4.53B | O17: 0.0372 | Q17: 42737 | R17: 2363.64 | S17: 2285.59 | T17: 2371.54 | U17: 2271.65 | W17: 0.0372 | Z17: 42737 | AA17: 83240 | AB17: 81754 | AC17: 84320 | AD17: 80803 | AF17: 0.0193 | AH17: 42737 | AI17: 1248.52 | AJ17: 1210.6 | AK17: 1264.18 | AL17: 1198.04 | AN17: 0.0314 | AQ17: Dec-25 | AR17: 104.19 | AS17: 103.98 | AT17: 104.1 | AY17: 42826 | AZ17: 2017 | BA17: 4 | BB17: 69.1 | BC17: 69.4 | BD17: 68.7 | BE17: 2.99 | BF17: 3.02 | BG17: 3.03 | BI17: 42826 | BJ17: 64.536
A18: 42390 | B18: 7276.8 | C18: 7376.65 | D18: 7398.7 | E18: 7250 | F18: 248.11M | G18: -0.0044 | I18: 42738 | J18: 9173.75 | K18: 8904.4 | L18: 9218.4 | M18: 8860.1 | N18: 4.98B | O18: 0.0331 | Q18: 42738 | R18: 2362.72 | S18: 2380.13 | T18: 2400.98 | U18: 2322.25 | W18: -0.0004 | Z18: 42738 | AA18: 80979 | AB18: 83298 | AC18: 83646 | AD18: 78626 | AF18: -0.0272 | AH18: 42738 | AI18: 1248.63 | AJ18: 1248.57 | AK18: 1261.41 | AL18: 1194.89 | AN18: 0.0001 | AQ18: Jan-26 | AR18: 104.59 | AS18: 104.28 | AT18: 104.45 | AU18: 2.73 | AV18: 2.75 | AW18: 2.74 | AY18: 42856 | AZ18: 2017 | BA18: 5 | BB18: 69.2 | BC18: 69.6 | BD18: 68.8 | BE18: 2.18 | BF18: 2.3 | BG18: 2.13 | BI18: 42856 | BJ18: 64.4195
A19: 42391 | B19: 7422.45 | C19: 7355.7 | D19: 7433.4 | E19: 7327.6 | F19: 236.28M | G19: 0.02 | I19: 42739 | J19: 9304.05 | K19: 9220.6 | L19: 9367.15 | M19: 9075.15 | N19: 3.15B | O19: 0.0142 | Q19: 42739 | R19: 2384.2 | S19: 2362.34 | T19: 2398.16 | U19: 2328.95 | W19: 0.0091 | Z19: 42739 | AA19: 81472 | AB19: 80965 | AC19: 83544 | AD19: 80446 | AF19: 0.0061 | AH19: 42739 | AI19: 1267.65 | AJ19: 1248.3 | AK19: 1295.66 | AL19: 1243.69 | AN19: 0.0152 | AQ19: Feb-26 | AR19: 104.74 | AS19: 104.36 | AT19: 104.57 | AU19: 3.37 | AV19: 3.02 | AW19: 3.21 | AY19: 42887 | AZ19: 2017 | BA19: 6 | BB19: 69.5 | BC19: 69.9 | BD19: 69.1 | BE19: 1.46 | BF19: 1.52 | BG19: 1.41 | BI19: 42887 | BJ19: 64.4482
A20: 42394 | B20: 7436.15 | C20: 7468.75 | D20: 7487.15 | E20: 7421.2 | F20: 168.20M | G20: 0.0018 | I20: 42740 | J20: 9621.25 | K20: 9339.85 | L20: 9649.6 | M20: 9269.9 | N20: 4.68B | O20: 0.0341 | Q20: 42740 | R20: 2411.8 | S20: 2388.5 | T20: 2418.71 | U20: 2352.72 | W20: 0.0116 | Z20: 42740 | AA20: 81798 | AB20: 81552 | AC20: 82205 | AD20: 78521 | AF20: 0.004 | AH20: 42740 | AI20: 1268.09 | AJ20: 1268.5 | AK20: 1274.3 | AL20: 1214.18 | AN20: 0.0003 | AQ20: 46082 | AR20: 105.02 | AS20: 104.62 | AT20: 104.84 | AU20: 3.63 | AV20: 3.11 | AW20: 3.4 | AY20: 42917 | AZ20: 2017 | BA20: 7 | BB20: 70.7 | BC20: 71.1 | BD20: 70.1 | BE20: 2.36 | BF20: 2.41 | BG20: 2.17 | BI20: 42917 | BJ20: 64.424
A21: 42396 | B21: 7437.75 | C21: 7469.6 | D21: 7477.9 | E21: 7419.7 | F21: 193.39M | G21: 0.0002 | I21: 42741 | J21: 9520.9 | K21: 9603.55 | L21: 9709.3 | M21: 9448.75 | N21: 3.67B | O21: -0.0104 | Q21: 42741 | R21: 2423.41 | S21: 2415.65 | T21: 2453.82 | U21: 2405.7 | W21: 0.0048 | Z21: 42741 | AA21: 80200 | AB21: 81856 | AC21: 83512 | AD21: 79704 | AF21: -0.0195 | AH21: 42741 | AI21: 1241.2 | AJ21: 1268.9 | AK21: 1296.26 | AL21: 1236.78 | AN21: -0.0212 | AQ21: Apr-26 | AR21: 105.28 | AS21: 104.92 | AT21: 105.12 | AU21: 3.74 | AV21: 3.16 | AW21: 3.48 | AY21: 42948 | AZ21: 2017 | BA21: 8 | BB21: 71.3 | BC21: 72 | BD21: 70.6 | BE21: 3.28 | BF21: 3.22 | BG21: 3.35 | BI21: 42948 | BJ21: 63.9683
A22: 42397 | B22: 7424.65 | C22: 7426.5 | D22: 7468.85 | E22: 7409.6 | F22: 283.04M | G22: -0.0018 | I22: 42742 | J22: 10077.1 | K22: 9587.95 | L22: 10114.85 | M22: 9543.55 | N22: 3.85B | O22: 0.0584 | Q22: 42742 | R22: 2470.3 | S22: 2431.39 | T22: 2484.04 | U22: 2407.7 | W22: 0.0193 | Z22: 42742 | AA22: 81442 | AB22: 80242 | AC22: 81554 | AD22: 77754 | AF22: 0.0155 | AH22: 42742 | AI22: 1269.05 | AJ22: 1241.76 | AK22: 1271.29 | AL22: 1204.73 | AN22: 0.0224 | AQ22: May-26 | AR22: 106.11 | AS22: 105.66 | AT22: 105.91 | AU22: 4.25 | AV22: 3.53 | AW22: 3.93 | AY22: 42979 | AZ22: 2017 | BA22: 9 | BB22: 71.2 | BC22: 71.9 | BD22: 70.4 | BE22: 3.28 | BF22: 3.15 | BG22: 3.44 | BI22: 42979 | BJ22: 64.4775
A23: 42398 | B23: 7563.55 | C23: 7413.35 | D23: 7575.65 | E23: 7402.8 | F23: 307.93M | G23: 0.0187 | I23: 42743 | J23: 9917.9 | K23: 10101.05 | L23: 10137.85 | M23: 9685.55 | N23: 4.30B | O23: -0.0158 | Q23: 42743 | R23: 2471.65 | S23: 2477.1 | T23: 2490.87 | U23: 2417.35 | W23: 0.0005 | Z23: 42743 | AA23: 84490 | AB23: 81505 | AC23: 84896 | AD23: 79702 | AF23: 0.0374 | AH23: 42743 | AI23: 1321.6 | AJ23: 1269.05 | AK23: 1326.19 | AL23: 1251.36 | AN23: 0.0414 | AQ23: Jun-26 | AR23: 107.24 | AS23: 106.69 | AT23: 107 | AU23: 4.74 | AV23: 3.92 | AW23: 4.38 | AY23: 43009 | AZ23: 2017 | BA23: 10 | BB23: 71.7 | BC23: 72.2 | BD23: 71 | BE23: 3.58 | BF23: 3.36 | BG23: 3.81 | BI23: 43009 | BJ23: 65.0357
A24: 42401 | B24: 7555.95 | C24: 7589.5 | D24: 7600.45 | E24: 7541.25 | F24: 206.64M | G24: -0.001 | I24: 42744 | J24: 9788.6 | K24: 9937.65 | L24: 10178.95 | M24: 9687.55 | N24: 4.29B | O24: -0.013 | Q24: 42744 | R24: 2519.36 | S24: 2474.42 | T24: 2519.44 | U24: 2446.55 | W24: 0.0193 | Z24: 42744 | AA24: 83529 | AB24: 84524 | AC24: 86750 | AD24: 83314 | AF24: -0.0114 | AH24: 42744 | AI24: 1279.1 | AJ24: 1322.03 | AK24: 1357.74 | AL24: 1277.6 | AN24: -0.0322 | AQ24: Jul-26 | AR24: 108.34 | AS24: 107.45 | AT24: 107.95 | AU24: 4.84 | AV24: 3.96 | AW24: 4.45 | AY24: 43040 | AZ24: 2017 | BA24: 11 | BB24: 72.5 | BC24: 73.1 | BD24: 71.7 | BE24: 4.88 | BF24: 4.79 | BG24: 4.9 | BI24: 43040 | BJ24: 64.8435
A25: 42402 | B25: 7455.55 | C25: 7566.65 | D25: 7576.3 | E25: 7428.05 | F25: 237.34M | G25: -0.0133 | I25: 42745 | J25: 10335.3 | K25: 9893.3 | L25: 10384.5 | M25: 9831.05 | N25: 4.64B | O25: 0.0559 | Q25: 42745 | R25: 2575.26 | S25: 2521.2 | T25: 2582.98 | U25: 2520.4 | W25: 0.0222 | Z25: 42745 | AA25: 82297 | AB25: 83545 | AC25: 84587 | AD25: 82046 | AF25: -0.0147 | AH25: 42745 | AI25: 1271.2 | AJ25: 1279.2 | AK25: 1306.46 | AL25: 1260.51 | AN25: -0.0062 | AQ25: Aug-26* | AR25: 109.27 | AS25: 108.07 | AT25: 108.74 | AU25: 5.23 | AV25: 4.31 | AW25: 4.82 | AY25: 43070 | AZ25: 2017 | BA25: 12 | BB25: 72.3 | BC25: 73 | BD25: 71.3 | BE25: 5.21 | BF25: 5.27 | BG25: 5.09 | BI25: 43070 | BJ25: 64.2445
A26: 42403 | B26: 7361.8 | C26: 7392.45 | D26: 7419.4 | E26: 7350.3 | F26: 197.86M | G26: -0.0126 | I26: 42746 | J26: 10226.55 | K26: 10390.35 | L26: 10490.45 | M26: 10094 | N26: 4.79B | O26: -0.0105 | Q26: 42746 | R26: 2647.58 | S26: 2583.21 | T26: 2657.74 | U26: 2557.45 | W26: 0.0281 | Z26: 42746 | AA26: 82175 | AB26: 82293 | AC26: 84349 | AD26: 81713 | AF26: -0.0015 | AH26: 42746 | AI26: 1274.36 | AJ26: 1270.94 | AK26: 1299.44 | AL26: 1265.49 | AN26: 0.0025 | AQ26: *Index and Inflation for the month of August 2026 are provisional. | AY26: 43101 | AZ26: 2018 | BA26: 1 | BB26: 72.1 | BC26: 72.7 | BD26: 71.3 | BE26: 5.07 | BF26: 5.21 | BG26: 4.93 | BI26: 43101 | BJ26: 63.6452
A27: 42404 | B27: 7404 | C27: 7411.45 | D27: 7457.05 | E27: 7365.95 | F27: 229.56M | G27: 0.0057 | I27: 42747 | J27: 10530.7 | K27: 10263.7 | L27: 10552.4 | M27: 10033.35 | N27: 3.61B | O27: 0.0297 | Q27: 42747 | R27: 2673.61 | S27: 2645.1 | T27: 2694.97 | U27: 2605.52 | W27: 0.0098 | Z27: 42747 | AA27: 83135 | AB27: 82197 | AC27: 83501 | AD27: 79613 | AF27: 0.0117 | AH27: 42747 | AI27: 1302.45 | AJ27: 1274.59 | AK27: 1307.97 | AL27: 1236.27 | AN27: 0.022 | AY27: 43132 | AZ27: 2018 | BA27: 2 | BB27: 71.8 | BC27: 72.3 | BD27: 71.3 | BE27: 4.44 | BF27: 4.45 | BG27: 4.52 | BI27: 43132 | BJ27: 64.43
A28: 42405 | B28: 7489.1 | C28: 7418.25 | D28: 7503.15 | E28: 7406.65 | F28: 257.52M | G28: 0.0115 | I28: 43101 | J28: 11027.7 | K28: 10531.7 | L28: 11171.55 | M28: 10404.65 | N28: 4.84B | O28: 0.0472 | Q28: 43101 | R28: 2823.81 | S28: 2683.73 | T28: 2872.87 | U28: 2682.36 | W28: 0.0562 | Z28: 43101 | AA28: 85436 | AB28: 83174 | AC28: 86753 | AD28: 82887 | AF28: 0.0277 | AH28: 43101 | AI28: 1344.7 | AJ28: 1302.62 | AK28: 1366.26 | AL28: 1302.6 | AN28: 0.0324 | AY28: 43160 | AZ28: 2018 | BA28: 3 | BB28: 71.9 | BC28: 72.4 | BD28: 71.3 | BE28: 4.28 | BF28: 4.44 | BG28: 4.12 | BI28: 43160 | BJ28: 65.0455
A29: 42408 | B29: 7387.25 | C29: 7489.7 | D29: 7512.55 | E29: 7363.2 | F29: 176.76M | G29: -0.0136 | I29: 43102 | J29: 10492.85 | K29: 11044.55 | L29: 11117.35 | M29: 10276.3 | N29: 4.53B | O29: -0.0485 | Q29: 43102 | R29: 2713.83 | S29: 2816.45 | T29: 2835.96 | U29: 2532.69 | W29: -0.0389 | Z29: 43102 | AA29: 85917 | AB29: 85475 | AC29: 87307 | AD29: 83987 | AF29: 0.0056 | AH29: 43102 | AI29: 1317.66 | AJ29: 1345.08 | AK29: 1361.97 | AL29: 1306.99 | AN29: -0.0201 | AY29: 43191 | AZ29: 2018 | BA29: 4 | BB29: 72.2 | BC29: 72.6 | BD29: 71.7 | BE29: 4.58 | BF29: 4.67 | BG29: 4.42 | BI29: 43191 | BJ29: 65.6729
A30: 42409 | B30: 7298.2 | C30: 7303.95 | D30: 7323.45 | E30: 7275.15 | F30: 218.73M | G30: -0.0121 | I30: 43103 | J30: 10113.7 | K30: 10479.95 | L30: 10525.5 | M30: 9951.9 | N30: 4.52B | O30: -0.0361 | Q30: 43103 | R30: 2640.87 | S30: 2715.22 | T30: 2801.9 | U30: 2585.89 | W30: -0.0269 | Z30: 43103 | AA30: 86206 | AB30: 85957 | AC30: 87968 | AD30: 84907 | AF30: 0.0034 | AH30: 43103 | AI30: 1324 | AJ30: 1318.22 | AK30: 1356.87 | AL30: 1302.76 | AN30: 0.0048 | AY30: 43221 | AZ30: 2018 | BA30: 5 | BB30: 72.6 | BC30: 73 | BD30: 72 | BE30: 4.87 | BF30: 4.88 | BG30: 4.72 | BI30: 43221 | BJ30: 67.51
A31: 42410 | B31: 7215.7 | C31: 7264.3 | D31: 7271.85 | E31: 7177.75 | F31: 254.48M | G31: -0.0113 | I31: 43104 | J31: 10739.35 | K31: 10151.65 | L31: 10759 | M31: 10111.3 | N31: 4.95B | O31: 0.0619 | Q31: 43104 | R31: 2648.05 | S31: 2633.45 | T31: 2717.49 | U31: 2553.8 | W31: 0.0027 | Z31: 43104 | AA31: 87378 | AB31: 86356 | AC31: 89104 | AD31: 85848 | AF31: 0.0136 | AH31: 43104 | AI31: 1314.95 | AJ31: 1326.21 | AK31: 1365.37 | AL31: 1310.29 | AN31: -0.0068 | AY31: 43252 | AZ31: 2018 | BA31: 6 | BB31: 72.9 | BC31: 73.4 | BD31: 72.5 | BE31: 4.92 | BF31: 4.93 | BG31: 4.85 | BI31: 43252 | BJ31: 67.79
A32: 42411 | B32: 6976.35 | C32: 7203.6 | D32: 7208.65 | E32: 6959.95 | F32: 301.30M | G32: -0.0332 | I32: 43105 | J32: 10736.15 | K32: 10783.85 | L32: 10929.2 | M32: 10417.8 | N32: 5.50B | O32: -0.0003 | Q32: 43105 | R32: 2705.27 | S32: 2643.64 | T32: 2742.24 | U32: 2594.62 | W32: 0.0216 | Z32: 43105 | AA32: 87477 | AB32: 87421 | AC32: 89357 | AD32: 86592 | AF32: 0.0011 | AH32: 43105 | AI32: 1297.92 | AJ32: 1315.4 | AK32: 1326.17 | AL32: 1282 | AN32: -0.013 | AY32: 43282 | AZ32: 2018 | BA32: 7 | BB32: 73.6 | BC32: 74 | BD32: 73.2 | BE32: 4.17 | BF32: 4.11 | BG32: 4.32 | BI32: 43282 | BJ32: 68.6867
A33: 42412 | B33: 6980.95 | C33: 7023.65 | D33: 7034.8 | E33: 6869 | F33: 344.21M | G33: 0.0007 | I33: 43106 | J33: 10714.3 | K33: 10738.45 | L33: 10893.25 | M33: 10550.9 | N33: 4.83B | O33: -0.002 | Q33: 43106 | R33: 2718.37 | S33: 2718.7 | T33: 2791.47 | U33: 2691.99 | W33: 0.0048 | Z33: 43106 | AA33: 85717 | AB33: 87562 | AC33: 88525 | AD33: 85404 | AF33: -0.0201 | AH33: 43106 | AI33: 1252.25 | AJ33: 1298.79 | AK33: 1309.64 | AL33: 1245.67 | AN33: -0.0352 | AY33: 43313 | AZ33: 2018 | BA33: 8 | BB33: 73.9 | BC33: 74.4 | BD33: 73.4 | BE33: 3.69 | BF33: 3.41 | BG33: 3.99 | BI33: 43313 | BJ33: 69.6317
A34: 42415 | B34: 7162.95 | C34: 7057.35 | D34: 7182.8 | E34: 7056.8 | F34: 365.22M | G34: 0.0261 | I34: 43107 | J34: 11356.5 | K34: 10732.35 | L34: 11366 | M34: 10604.65 | N34: 5.29B | O34: 0.0599 | Q34: 43107 | R34: 2816.29 | S34: 2704.95 | T34: 2848.03 | U34: 2698.95 | W34: 0.036 | Z34: 43107 | AA34: 83742 | AB34: 85814 | AC34: 87031 | AD34: 83265 | AF34: -0.023 | AH34: 43107 | AI34: 1223.41 | AJ34: 1253.49 | AK34: 1266.26 | AL34: 1211.48 | AN34: -0.023 | AY34: 43344 | AZ34: 2018 | BA34: 9 | BB34: 73.8 | BC34: 74.2 | BD34: 73.5 | BE34: 3.7 | BF34: 3.27 | BG34: 4.31 | BI34: 43344 | BJ34: 72.2779
A35: 42416 | B35: 7048.25 | C35: 7201.25 | D35: 7204.65 | E35: 7037.7 | F35: 261.61M | G35: -0.016 | I35: 43108 | J35: 11680.5 | K35: 11359.8 | L35: 11760.2 | M35: 11234.95 | N35: 5.41B | O35: 0.0285 | Q35: 43108 | R35: 2901.52 | S35: 2821.17 | T35: 2916.5 | U35: 2796.34 | W35: 0.0303 | Z35: 43108 | AA35: 85250 | AB35: 83793 | AC35: 85782 | AD35: 81120 | AF35: 0.018 | AH35: 43108 | AI35: 1200.71 | AJ35: 1223.97 | AK35: 1225.1 | AL35: 1160.19 | AN35: -0.0186 | AY35: 43374 | AZ35: 2018 | BA35: 10 | BB35: 74.1 | BC35: 74.3 | BD35: 73.9 | BE35: 3.38 | BF35: 2.82 | BG35: 4.04 | BI35: 43374 | BJ35: 73.5609
A36: 42417 | B36: 7108.45 | C36: 7058.85 | D36: 7123.7 | E36: 6960.65 | F36: 268.02M | G36: 0.0085 | I36: 43109 | J36: 10930.45 | K36: 11751.8 | L36: 11751.8 | M36: 10850.3 | N36: 6.03B | O36: -0.0642 | Q36: 43109 | R36: 2913.98 | S36: 2896.96 | T36: 2940.91 | U36: 2864.12 | W36: 0.0043 | Z36: 43109 | AA36: 86398 | AB36: 85227 | AC36: 87852 | AD36: 84827 | AF36: 0.0135 | AH36: 43109 | AI36: 1191.69 | AJ36: 1200.29 | AK36: 1212.9 | AL36: 1180.68 | AN36: -0.0075 | AY36: 43405 | AZ36: 2018 | BA36: 11 | BB36: 74.2 | BC36: 74.4 | BD36: 73.9 | BE36: 2.33 | BF36: 1.71 | BG36: 3.12 | BI36: 43405 | BJ36: 71.738
A37: 42418 | B37: 7191.75 | C37: 7177.4 | D37: 7215.1 | E37: 7127.85 | F37: 254.33M | G37: 0.0117 | I37: 43110 | J37: 10386.6 | K37: 10930.9 | L37: 11035.65 | M37: 10004.55 | N37: 8.14B | O37: -0.0498 | Q37: 43110 | R37: 2711.74 | S37: 2926.29 | T37: 2939.86 | U37: 2603.54 | W37: -0.0694 | Z37: 43110 | AA37: 89774 | AB37: 86446 | AC37: 91357 | AD37: 86134 | AF37: 0.0391 | AH37: 43110 | AI37: 1214.14 | AJ37: 1192.19 | AK37: 1243.63 | AL37: 1183.24 | AN37: 0.0188 | AY37: 43435 | AZ37: 2018 | BA37: 12 | BB37: 73.8 | BC37: 74.1 | BD37: 73.4 | BE37: 2.11 | BF37: 1.5 | BG37: 2.91 | BI37: 43435 | BJ37: 70.8331
A38: 42419 | B38: 7210.75 | C38: 7170.55 | D38: 7226.85 | E38: 7145.95 | F38: 198.21M | G38: 0.0026 | I38: 43111 | J38: 10876.75 | K38: 10441.7 | L38: 10922.45 | M38: 10341.9 | N38: 6.79B | O38: 0.0472 | Q38: 43111 | R38: 2760.17 | S38: 2717.58 | T38: 2815.15 | U38: 2631.09 | W38: 0.0179 | Z38: 43111 | AA38: 85092 | AB38: 89827 | AC38: 90919 | AD38: 84692 | AF38: -0.0522 | AH38: 43111 | AI38: 1221.88 | AJ38: 1215.24 | AK38: 1237.74 | AL38: 1196.19 | AN38: 0.0064 | AY38: 43466 | AZ38: 2019 | BA38: 1 | BB38: 73.5 | BC38: 73.6 | BD38: 73.4 | BE38: 1.97 | BF38: 1.22 | BG38: 2.91 | BI38: 43466 | BJ38: 70.71
... A130: 42558 | B130: 8337.9 | C130: 8342 | D130: 8361.95 | E130: 8317.7 | F130: 160.33M | G130: 0.0002 | I130: 46029 | J130: 24383.6 | K130: 23897.65 | L130: 24530.9 | M130: 23606.3 | N130: 8.19B | O130: 0.0217 | Q130: 46029 | R130: 7489.72 | S130: 7478.84 | T130: 7581.5 | U130: 7313.92 | W130: -0.0013 | Z130: 46029 | AA130: 385566 | AB130: 379302 | AC130: 402352 | AD130: 375161 | AF130: 0.0163 | AH130: 46029 | AI130: 4042.67 | AJ130: 4008.49 | AK130: 4202.67 | AL130: 3959.69 | AN130: 0.0085 | AY130: 46266 | AZ130: 2026 | BA130: 9 | BB130: 114.09001 | BC130: 115.09409 | BD130: 112.83589 | BE130: 4.92 | BF130: 5.32 | BG130: 4.41 | BI130: 46266 | BJ130: 95.5124
A131: 42559 | B131: 8323.2 | C131: 8350 | D131: 8353.3 | E131: 8287.55 | F131: 142.16M | G131: -0.0018 | I131: 46030 | J131: 24080.4 | K131: 24572.7 | L131: 24774.3 | M131: 23993.6 | N131: 6.27B | O131: -0.0124 | Q131: 46030 | R131: 7686.14 | S131: 7504.78 | T131: 7816.7 | U131: 7504.78 | W131: 0.0262 | Z131: 46030 | AA131: 423300 | AB131: 385618 | AC131: 449801 | AD131: 383199 | AF131: 0.0979 | AH131: 46030 | AI131: 4448.92 | AJ131: 4077.11 | AK131: 4697.66 | AL131: 4019.19 | AN131: 0.1005
...

Sheet Monthly Data
A1: Month | B1: USD/INR avg | C1: Gold USD/oz | D1: Gold INR/oz (source) | E1: Nifty 50 TRI | F1: S&P 500 total return index | G1: India CPI index | H1: S&P 500 US equity value in INR (index) | I1: FX monthly return | J1: Gold USD return | K1: Gold INR source return | L1: Nifty TRI return | M1: S&P 500 USD return | N1: S&P 500 INR return | O1: India CPI inflation | P1: Gold INR drawdown | Q1: Nifty drawdown | R1: S&P 500 INR drawdown | S1: ₹100,000 Gold INR value | T1: ₹100,000 Nifty value | U1: ₹100,000 S&P 500 INR value | V1: Real Gold value (base-month ₹) | W1: Real Nifty value (base-month ₹) | X1: Real S&P value (base-month ₹) | AA1: Inferences
A2: 42370 | B2: 67.3332 | C2: 1117.64 | D2: 75852 | E2: 7563.55 | F2: 1940.24 | G2: 66.5 | H2: =F2*B2 -> 130642.57
A3: 42401 | B3: 68.2395 | C3: 1237.76 | D3: 84450 | E3: 6987.05 | F3: 1932.23 | G3: 66.4 | H3: =F3*B3 -> 131854.41 | I3: =IF(OR(B3="",B2=""),"",B3/B2-1) -> 0.013459928 | J3: =IF(OR(C3="",C2=""),"",C3/C2-1) -> 0.10747647 | K3: =IF(OR(D3="",D2=""),"",D3/D2-1) -> 0.11335232 | L3: =IF(OR(E3="",E2=""),"",E3/E2-1) -> -0.076220822 | M3: =IF(OR(F3="",F2=""),"",F3/F2-1) -> -0.0041283553 | N3: =IF(OR(H3="",H2=""),"",H3/H2-1) -> 0.009276005 | O3: =IF(OR(G3="",G2=""),"",G3/G2-1) -> -0.0015037594 | P3: =IF(D3="","",D3/MAX($D$2:D3)-1) -> 0 | Q3: =IF(E3="","",E3/MAX($E$2:E3)-1) -> -0.076220822 | R3: =IF(H3="","",H3/MAX($H$2:H3)-1) -> 0 | S3: =IF(D3="","",100000*D3/$D$2) -> 111335.23 | T3: =IF(E3="","",100000*E3/$E$2) -> 92377.918 | U3: =IF(H3="","",100000*H3/$H$2) -> 100927.6 | V3: =IF(OR(S3="",G3="",$G$2=""),"",S3*$G$2/G3) -> 111502.91 | W3: =IF(OR(T3="",G3="",$G$2=""),"",T3*$G$2/G3) -> 92517.041 | X3: =IF(OR(U3="",G3="",$G$2=""),"",U3*$G$2/G3) -> 101079.6 | AA3: 1. On the supplied monthly series, the S&P 500 converted into INR has the highest historical CAGR, with source INR gold close behind; Nifty 50 TRI has the lowest CAGR of the three.
A4: 42430 | B4: 66.8909 | C4: 1231.95 | D4: 81617 | E4: 7738.4 | F4: 2059.74 | G4: 66.4 | H4: =F4*B4 -> 137777.86 | I4: =IF(OR(B4="",B3=""),"",B4/B3-1) -> -0.019762747 | J4: =IF(OR(C4="",C3=""),"",C4/C3-1) -> -0.0046939633 | K4: =IF(OR(D4="",D3=""),"",D4/D3-1) -> -0.033546477 | L4: =IF(OR(E4="",E3=""),"",E4/E3-1) -> 0.10753465 | M4: =IF(OR(F4="",F3=""),"",F4/F3-1) -> 0.065991109 | N4: =IF(OR(H4="",H3=""),"",H4/H3-1) -> 0.044924196 | O4: =IF(OR(G4="",G3=""),"",G4/G3-1) -> 0 | P4: =IF(D4="","",D4/MAX($D$2:D4)-1) -> -0.033546477 | Q4: =IF(E4="","",E4/MAX($E$2:E4)-1) -> 0 | R4: =IF(H4="","",H4/MAX($H$2:H4)-1) -> 0 | S4: =IF(D4="","",100000*D4/$D$2) -> 107600.33 | T4: =IF(E4="","",100000*E4/$E$2) -> 102311.75 | U4: =IF(H4="","",100000*H4/$H$2) -> 105461.69 | V4: =IF(OR(S4="",G4="",$G$2=""),"",S4*$G$2/G4) -> 107762.38 | W4: =IF(OR(T4="",G4="",$G$2=""),"",T4*$G$2/G4) -> 102465.83 | X4: =IF(OR(U4="",G4="",$G$2=""),"",U4*$G$2/G4) -> 105620.52 | AA4: 2. Nifty 50 TRI shows the deepest maximum drawdown in the supplied monthly observations. This indicates that the strongest or weakest long-run return alone does not describe the investor experience.
A5: 42461 | B5: 66.4219 | C5: 1293.36 | D5: 85898 | E5: 7849.8 | F5: 2065.3 | G5: 67 | H5: =F5*B5 -> 137181.15 | I5: =IF(OR(B5="",B4=""),"",B5/B4-1) -> -0.0070114171 | J5: =IF(OR(C5="",C4=""),"",C5/C4-1) -> 0.049847802 | K5: =IF(OR(D5="",D4=""),"",D5/D4-1) -> 0.052452308 | L5: =IF(OR(E5="",E4=""),"",E5/E4-1) -> 0.014395741 | M5: =IF(OR(F5="",F4=""),"",F5/F4-1) -> 0.0026993698 | N5: =IF(OR(H5="",H4=""),"",H5/H4-1) -> -0.0043309737 | O5: =IF(OR(G5="",G4=""),"",G5/G4-1) -> 0.0090361446 | P5: =IF(D5="","",D5/MAX($D$2:D5)-1) -> 0 | Q5: =IF(E5="","",E5/MAX($E$2:E5)-1) -> 0 | R5: =IF(H5="","",H5/MAX($H$2:H5)-1) -> -0.0043309737 | S5: =IF(D5="","",100000*D5/$D$2) -> 113244.21 | T5: =IF(E5="","",100000*E5/$E$2) -> 103784.6 | U5: =IF(H5="","",100000*H5/$H$2) -> 105004.94 | V5: =IF(OR(S5="",G5="",$G$2=""),"",S5*$G$2/G5) -> 112399.11 | W5: =IF(OR(T5="",G5="",$G$2=""),"",T5*$G$2/G5) -> 103010.09 | X5: =IF(OR(U5="",G5="",$G$2=""),"",U5*$G$2/G5) -> 104221.32 | AA5: 3. INR conversion matters: the return to an Indian investor in a USD-denominated asset reflects both the underlying USD asset return and changes in USD/INR. The current S&P conversion uses monthly-average FX, so it is a proxy rather than a strict month-end valuation.
A6: 42491 | B6: 66.8895 | C6: 1214.69 | D6: 81626 | E6: 8160.1 | F6: 2096.96 | G6: 67.7 | H6: =F6*B6 -> 140264.61 | I6: =IF(OR(B6="",B5=""),"",B6/B5-1) -> 0.0070398468 | J6: =IF(OR(C6="",C5=""),"",C6/C5-1) -> -0.060826065 | K6: =IF(OR(D6="",D5=""),"",D6/D5-1) -> -0.049733405 | L6: =IF(OR(E6="",E5=""),"",E6/E5-1) -> 0.03952967 | M6: =IF(OR(F6="",F5=""),"",F6/F5-1) -> 0.015329492 | N6: =IF(OR(H6="",H5=""),"",H6/H5-1) -> 0.022477256 | O6: =IF(OR(G6="",G5=""),"",G6/G5-1) -> 0.010447761 | P6: =IF(D6="","",D6/MAX($D$2:D6)-1) -> -0.049733405 | Q6: =IF(E6="","",E6/MAX($E$2:E6)-1) -> 0 | R6: =IF(H6="","",H6/MAX($H$2:H6)-1) -> 0 | S6: =IF(D6="","",100000*D6/$D$2) -> 107612.19 | T6: =IF(E6="","",100000*E6/$E$2) -> 107887.17 | U6: =IF(H6="","",100000*H6/$H$2) -> 107365.16 | V6: =IF(OR(S6="",G6="",$G$2=""),"",S6*$G$2/G6) -> 105704.74 | W6: =IF(OR(T6="",G6="",$G$2=""),"",T6*$G$2/G6) -> 105974.84 | X6: =IF(OR(U6="",G6="",$G$2=""),"",U6*$G$2/G6) -> 105462.09 | AA6: 4. Gold INR source prices and USD gold converted using USD/INR can differ because of source timing, local pricing, premiums, taxes, and market conventions. The table uses the source INR series for the reported Gold INR performance.
A7: 42522 | B7: 67.2655 | C7: 1321.78 | D7: 89212 | E7: 8287.75 | F7: 2098.86 | G7: 68.5 | H7: =F7*B7 -> 141180.87 | I7: =IF(OR(B7="",B6=""),"",B7/B6-1) -> 0.0056212111 | J7: =IF(OR(C7="",C6=""),"",C7/C6-1) -> 0.088162412 | K7: =IF(OR(D7="",D6=""),"",D7/D6-1) -> 0.092936074 | L7: =IF(OR(E7="",E6=""),"",E7/E6-1) -> 0.015643191 | M7: =IF(OR(F7="",F6=""),"",F7/F6-1) -> 0.00090607355 | N7: =IF(OR(H7="",H6=""),"",H7/H6-1) -> 0.0065323779 | O7: =IF(OR(G7="",G6=""),"",G7/G6-1) -> 0.011816839 | P7: =IF(D7="","",D7/MAX($D$2:D7)-1) -> 0 | Q7: =IF(E7="","",E7/MAX($E$2:E7)-1) -> 0 | R7: =IF(H7="","",H7/MAX($H$2:H7)-1) -> 0 | S7: =IF(D7="","",100000*D7/$D$2) -> 117613.25 | T7: =IF(E7="","",100000*E7/$E$2) -> 109574.87 | U7: =IF(H7="","",100000*H7/$H$2) -> 108066.51 | V7: =IF(OR(S7="",G7="",$G$2=""),"",S7*$G$2/G7) -> 114179.28 | W7: =IF(OR(T7="",G7="",$G$2=""),"",T7*$G$2/G7) -> 106375.6 | X7: =IF(OR(U7="",G7="",$G$2=""),"",U7*$G$2/G7) -> 104911.29 | AA7: 5. Nominal returns are not the same as purchasing-power growth. Use a consistent, verified CPI series and the same start/end dates before presenting real-return conclusions.
A8: 42552 | B8: 67.158 | C8: 1350.59 | D8: 89974 | E8: 8638.5 | F8: 2173.6 | G8: 69.1 | H8: =F8*B8 -> 145974.63 | I8: =IF(OR(B8="",B7=""),"",B8/B7-1) -> -0.0015981447 | J8: =IF(OR(C8="",C7=""),"",C8/C7-1) -> 0.021796366 | K8: =IF(OR(D8="",D7=""),"",D8/D7-1) -> 0.0085414518 | L8: =IF(OR(E8="",E7=""),"",E8/E7-1) -> 0.042321499 | M8: =IF(OR(F8="",F7=""),"",F8/F7-1) -> 0.035609807 | N8: =IF(OR(H8="",H7=""),"",H8/H7-1) -> 0.033954753 | O8: =IF(OR(G8="",G7=""),"",G8/G7-1) -> 0.0087591241 | P8: =IF(D8="","",D8/MAX($D$2:D8)-1) -> 0 | Q8: =IF(E8="","",E8/MAX($E$2:E8)-1) -> 0 | R8: =IF(H8="","",H8/MAX($H$2:H8)-1) -> 0 | S8: =IF(D8="","",100000*D8/$D$2) -> 118617.83 | T8: =IF(E8="","",100000*E8/$E$2) -> 114212.24 | U8: =IF(H8="","",100000*H8/$H$2) -> 111735.88 | V8: =IF(OR(S8="",G8="",$G$2=""),"",S8*$G$2/G8) -> 114154.65 | W8: =IF(OR(T8="",G8="",$G$2=""),"",T8*$G$2/G8) -> 109914.82 | X8: =IF(OR(U8="",G8="",$G$2=""),"",U8*$G$2/G8) -> 107531.64
A9: 42583 | B9: 66.9035 | C9: 1308.45 | D9: 87617 | E9: 8786.2 | F9: 2170.95 | G9: 69.1 | H9: =F9*B9 -> 145244.15 | I9: =IF(OR(B9="",B8=""),"",B9/B8-1) -> -0.0037895709 | J9: =IF(OR(C9="",C8=""),"",C9/C8-1) -> -0.031201179 | K9: =IF(OR(D9="",D8=""),"",D9/D8-1) -> -0.026196457 | L9: =IF(OR(E9="",E8=""),"",E9/E8-1) -> 0.017097876 | M9: =IF(OR(F9="",F8=""),"",F9/F8-1) -> -0.0012191756 | N9: =IF(OR(H9="",H8=""),"",H9/H8-1) -> -0.0050041263 | O9: =IF(OR(G9="",G8=""),"",G9/G8-1) -> 0 | P9: =IF(D9="","",D9/MAX($D$2:D9)-1) -> -0.026196457 | Q9: =IF(E9="","",E9/MAX($E$2:E9)-1) -> 0 | R9: =IF(H9="","",H9/MAX($H$2:H9)-1) -> -0.0050041263 | S9: =IF(D9="","",100000*D9/$D$2) -> 115510.47 | T9: =IF(E9="","",100000*E9/$E$2) -> 116165.03 | U9: =IF(H9="","",100000*H9/$H$2) -> 111176.74 | V9: =IF(OR(S9="",G9="",$G$2=""),"",S9*$G$2/G9) -> 111164.2 | W9: =IF(OR(T9="",G9="",$G$2=""),"",T9*$G$2/G9) -> 111794.13 | X9: =IF(OR(U9="",G9="",$G$2=""),"",U9*$G$2/G9) -> 106993.54
A10: 42614 | B10: 66.7138 | C10: 1315.8 | D10: 87561 | E10: 8611.15 | F10: 2168.27 | G10: 68.9 | H10: =F10*B10 -> 144653.53 | I10: =IF(OR(B10="",B9=""),"",B10/B9-1) -> -0.0028354271 | J10: =IF(OR(C10="",C9=""),"",C10/C9-1) -> 0.0056173335 | K10: =IF(OR(D10="",D9=""),"",D10/D9-1) -> -0.00063914537 | L10: =IF(OR(E10="",E9=""),"",E10/E9-1) -> -0.019923289 | M10: =IF(OR(F10="",F9=""),"",F10/F9-1) -> -0.0012344826 | N10: =IF(OR(H10="",H9=""),"",H10/H9-1) -> -0.0040664095 | O10: =IF(OR(G10="",G9=""),"",G10/G9-1) -> -0.002894356 | P10: =IF(D10="","",D10/MAX($D$2:D10)-1) -> -0.026818859 | Q10: =IF(E10="","",E10/MAX($E$2:E10)-1) -> -0.019923289 | R10: =IF(H10="","",H10/MAX($H$2:H10)-1) -> -0.0090501869 | S10: =IF(D10="","",100000*D10/$D$2) -> 115436.64 | T10: =IF(E10="","",100000*E10/$E$2) -> 113850.64 | U10: =IF(H10="","",100000*H10/$H$2) -> 110724.65 | V10: =IF(OR(S10="",G10="",$G$2=""),"",S10*$G$2/G10) -> 111415.62 | W10: =IF(OR(T10="",G10="",$G$2=""),"",T10*$G$2/G10) -> 109884.87 | X10: =IF(OR(U10="",G10="",$G$2=""),"",U10*$G$2/G10) -> 106867.77
A11: 42644 | B11: 66.7415 | C11: 1277.28 | D11: 85163 | E11: 8625.7 | F11: 2126.15 | G11: 69.2 | H11: =F11*B11 -> 141902.44 | I11: =IF(OR(B11="",B10=""),"",B11/B10-1) -> 0.00041520645 | J11: =IF(OR(C11="",C10=""),"",C11/C10-1) -> -0.029274966 | K11: =IF(OR(D11="",D10=""),"",D11/D10-1) -> -0.027386622 | L11: =IF(OR(E11="",E10=""),"",E11/E10-1) -> 0.0016896698 | M11: =IF(OR(F11="",F10=""),"",F11/F10-1) -> -0.019425625 | N11: =IF(OR(H11="",H10=""),"",H11/H10-1) -> -0.019018484 | O11: =IF(OR(G11="",G10=""),"",G11/G10-1) -> 0.0043541364 | P11: =IF(D11="","",D11/MAX($D$2:D11)-1) -> -0.053471003 | Q11: =IF(E11="","",E11/MAX($E$2:E11)-1) -> -0.018267283 | R11: =IF(H11="","",H11/MAX($H$2:H11)-1) -> -0.02789655 | S11: =IF(D11="","",100000*D11/$D$2) -> 112275.22 | T11: =IF(E11="","",100000*E11/$E$2) -> 114043.01 | U11: =IF(H11="","",100000*H11/$H$2) -> 108618.84 | V11: =IF(OR(S11="",G11="",$G$2=""),"",S11*$G$2/G11) -> 107894.54 | W11: =IF(OR(T11="",G11="",$G$2=""),"",T11*$G$2/G11) -> 109593.35 | X11: =IF(OR(U11="",G11="",$G$2=""),"",U11*$G$2/G11) -> 104380.82
A12: 42675 | B12: 67.6395 | C12: 1172.7 | D12: 80464 | E12: 8224.5 | F12: 2198.81 | G12: 69.1 | H12: =F12*B12 -> 148726.41 | I12: =IF(OR(B12="",B11=""),"",B12/B11-1) -> 0.013454897 | J12: =IF(OR(C12="",C11=""),"",C12/C11-1) -> -0.081877114 | K12: =IF(OR(D12="",D11=""),"",D12/D11-1) -> -0.055176544 | L12: =IF(OR(E12="",E11=""),"",E12/E11-1) -> -0.046512167 | M12: =IF(OR(F12="",F11=""),"",F12/F11-1) -> 0.034174447 | N12: =IF(OR(H12="",H11=""),"",H12/H11-1) -> 0.048089157 | O12: =IF(OR(G12="",G11=""),"",G12/G11-1) -> -0.0014450867 | P12: =IF(D12="","",D12/MAX($D$2:D12)-1) -> -0.1056972 | Q12: =IF(E12="","",E12/MAX($E$2:E12)-1) -> -0.063929799 | R12: =IF(H12="","",H12/MAX($H$2:H12)-1) -> 0 | S12: =IF(D12="","",100000*D12/$D$2) -> 106080.26 | T12: =IF(E12="","",100000*E12/$E$2) -> 108738.62 | U12: =IF(H12="","",100000*H12/$H$2) -> 113842.23 | V12: =IF(OR(S12="",G12="",$G$2=""),"",S12*$G$2/G12) -> 102088.82 | W12: =IF(OR(T12="",G12="",$G$2=""),"",T12*$G$2/G12) -> 104647.15 | X12: =IF(OR(U12="",G12="",$G$2=""),"",U12*$G$2/G12) -> 109558.73
A13: 42705 | B13: 67.8052 | C13: 1151.46 | D13: 78235 | E13: 8185.8 | F13: 2238.83 | G13: 68.7 | H13: =F13*B13 -> 151804.32 | I13: =IF(OR(B13="",B12=""),"",B13/B12-1) -> 0.002449752 | J13: =IF(OR(C13="",C12=""),"",C13/C12-1) -> -0.018112049 | K13: =IF(OR(D13="",D12=""),"",D13/D12-1) -> -0.027701829 | L13: =IF(OR(E13="",E12=""),"",E13/E12-1) -> -0.0047054532 | M13: =IF(OR(F13="",F12=""),"",F13/F12-1) -> 0.018200754 | N13: =IF(OR(H13="",H12=""),"",H13/H12-1) -> 0.020695093 | O13: =IF(OR(G13="",G12=""),"",G13/G12-1) -> -0.005788712 | P13: =IF(D13="","",D13/MAX($D$2:D13)-1) -> -0.13047102 | Q13: =IF(E13="","",E13/MAX($E$2:E13)-1) -> -0.068334434 | R13: =IF(H13="","",H13/MAX($H$2:H13)-1) -> 0 | S13: =IF(D13="","",100000*D13/$D$2) -> 103141.64 | T13: =IF(E13="","",100000*E13/$E$2) -> 108226.96 | U13: =IF(H13="","",100000*H13/$H$2) -> 116198.2 | V13: =IF(OR(S13="",G13="",$G$2=""),"",S13*$G$2/G13) -> 99838.71 | W13: =IF(OR(T13="",G13="",$G$2=""),"",T13*$G$2/G13) -> 104761.17 | X13: =IF(OR(U13="",G13="",$G$2=""),"",U13*$G$2/G13) -> 112477.15
A14: 42736 | B14: 68.0474 | C14: 1210.51 | D14: 81660 | E14: 8561.3 | F14: 2278.87 | G14: 68.6 | H14: =F14*B14 -> 155071.18 | I14: =IF(OR(B14="",B13=""),"",B14/B13-1) -> 0.0035719974 | J14: =IF(OR(C14="",C13=""),"",C14/C13-1) -> 0.051282719 | K14: =IF(OR(D14="",D13=""),"",D14/D13-1) -> 0.04377836 | L14: =IF(OR(E14="",E13=""),"",E14/E13-1) -> 0.04587212 | M14: =IF(OR(F14="",F13=""),"",F14/F13-1) -> 0.017884341 | N14: =IF(OR(H14="",H13=""),"",H14/H13-1) -> 0.021520222 | O14: =IF(OR(G14="",G13=""),"",G14/G13-1) -> -0.0014556041 | P14: =IF(D14="","",D14/MAX($D$2:D14)-1) -> -0.092404472 | Q14: =IF(E14="","",E14/MAX($E$2:E14)-1) -> -0.025596959 | R14: =IF(H14="","",H14/MAX($H$2:H14)-1) -> 0 | S14: =IF(D14="","",100000*D14/$D$2) -> 107657.02 | T14: =IF(E14="","",100000*E14/$E$2) -> 113191.56 | U14: =IF(H14="","",100000*H14/$H$2) -> 118698.81 | V14: =IF(OR(S14="",G14="",$G$2=""),"",S14*$G$2/G14) -> 104361.39 | W14: =IF(OR(T14="",G14="",$G$2=""),"",T14*$G$2/G14) -> 109726.51 | X14: =IF(OR(U14="",G14="",$G$2=""),"",U14*$G$2/G14) -> 115065.18
A15: 42767 | B15: 66.9726 | C15: 1248.52 | D15: 83240 | E15: 8879.6 | F15: 2363.64 | G15: 68.8 | H15: =F15*B15 -> 158299.12 | I15: =IF(OR(B15="",B14=""),"",B15/B14-1) -> -0.015794872 | J15: =IF(OR(C15="",C14=""),"",C15/C14-1) -> 0.031399988 | K15: =IF(OR(D15="",D14=""),"",D15/D14-1) -> 0.019348518 | L15: =IF(OR(E15="",E14=""),"",E15/E14-1) -> 0.037178933 | M15: =IF(OR(F15="",F14=""),"",F15/F14-1) -> 0.037198261 | N15: =IF(OR(H15="",H14=""),"",H15/H14-1) -> 0.020815846 | O15: =IF(OR(G15="",G14=""),"",G15/G14-1) -> 0.0029154519 | P15: =IF(D15="","",D15/MAX($D$2:D15)-1) -> -0.074843844 | Q15: =IF(E15="","",E15/MAX($E$2:E15)-1) -> 0 | R15: =IF(H15="","",H15/MAX($H$2:H15)-1) -> 0 | S15: =IF(D15="","",100000*D15/$D$2) -> 109740.02 | T15: =IF(E15="","",100000*E15/$E$2) -> 117399.9 | U15: =IF(H15="","",100000*H15/$H$2) -> 121169.63 | V15: =IF(OR(S15="",G15="",$G$2=""),"",S15*$G$2/G15) -> 106071.39 | W15: =IF(OR(T15="",G15="",$G$2=""),"",T15*$G$2/G15) -> 113475.19 | X15: =IF(OR(U15="",G15="",$G$2=""),"",U15*$G$2/G15) -> 117118.9
A16: 42795 | B16: 65.8009 | C16: 1248.63 | D16: 80979 | E16: 9173.75 | F16: 2362.72 | G16: 68.9 | H16: =F16*B16 -> 155469.1 | I16: =IF(OR(B16="",B15=""),"",B16/B15-1) -> -0.017495214 | J16: =IF(OR(C16="",C15=""),"",C16/C15-1) -> 8.8104316e-05 | K16: =IF(OR(D16="",D15=""),"",D16/D15-1) -> -0.027162422 | L16: =IF(OR(E16="",E15=""),"",E16/E15-1) -> 0.033126492 | M16: =IF(OR(F16="",F15=""),"",F16/F15-1) -> -0.00038923017 | N16: =IF(OR(H16="",H15=""),"",H16/H15-1) -> -0.017877635 | O16: =IF(OR(G16="",G15=""),"",G16/G15-1) -> 0.0014534884 | P16: =IF(D16="","",D16/MAX($D$2:D16)-1) -> -0.099973326 | Q16: =IF(E16="","",E16/MAX($E$2:E16)-1) -> 0 | R16: =IF(H16="","",H16/MAX($H$2:H16)-1) -> -0.017877635 | S16: =IF(D16="","",100000*D16/$D$2) -> 106759.22 | T16: =IF(E16="","",100000*E16/$E$2) -> 121288.95 | U16: =IF(H16="","",100000*H16/$H$2) -> 119003.4 | V16: =IF(OR(S16="",G16="",$G$2=""),"",S16*$G$2/G16) -> 103040.46 | W16: =IF(OR(T16="",G16="",$G$2=""),"",T16*$G$2/G16) -> 117064.08 | X16: =IF(OR(U16="",G16="",$G$2=""),"",U16*$G$2/G16) -> 114858.15
A17: 42826 | B17: 64.536 | C17: 1267.65 | D17: 81472 | E17: 9304.05 | F17: 2384.2 | G17: 69.1 | H17: =F17*B17 -> 153866.73 | I17: =IF(OR(B17="",B16=""),"",B17/B16-1) -> -0.019223141 | J17: =IF(OR(C17="",C16=""),"",C17/C16-1) -> 0.015232695 | K17: =IF(OR(D17="",D16=""),"",D17/D16-1) -> 0.0060879981 | L17: =IF(OR(E17="",E16=""),"",E17/E16-1) -> 0.01420357 | M17: =IF(OR(F17="",F16=""),"",F17/F16-1) -> 0.0090912169 | N17: =IF(OR(H17="",H16=""),"",H17/H16-1) -> -0.010306686 | O17: =IF(OR(G17="",G16=""),"",G17/G16-1) -> 0.0029027576 | P17: =IF(D17="","",D17/MAX($D$2:D17)-1) -> -0.094493965 | Q17: =IF(E17="","",E17/MAX($E$2:E17)-1) -> 0 | R17: =IF(H17="","",H17/MAX($H$2:H17)-1) -> -0.028000062 | S17: =IF(D17="","",100000*D17/$D$2) -> 107409.17 | T17: =IF(E17="","",100000*E17/$E$2) -> 123011.68 | U17: =IF(H17="","",100000*H17/$H$2) -> 117776.87 | V17: =IF(OR(S17="",G17="",$G$2=""),"",S17*$G$2/G17) -> 103367.72 | W17: =IF(OR(T17="",G17="",$G$2=""),"",T17*$G$2/G17) -> 118383.17 | X17: =IF(OR(U17="",G17="",$G$2=""),"",U17*$G$2/G17) -> 113345.33
A18: 42856 | B18: 64.4195 | C18: 1268.09 | D18: 81798 | E18: 9621.25 | F18: 2411.8 | G18: 69.2 | H18: =F18*B18 -> 155366.95 | I18: =IF(OR(B18="",B17=""),"",B18/B17-1) -> -0.001805194 | J18: =IF(OR(C18="",C17=""),"",C18/C17-1) -> 0.00034709896 | K18: =IF(OR(D18="",D17=""),"",D18/D17-1) -> 0.0040013747 | L18: =IF(OR(E18="",E17=""),"",E18/E17-1) -> 0.03409268 | M18: =IF(OR(F18="",F17=""),"",F18/F17-1) -> 0.01157621 | N18: =IF(OR(H18="",H17=""),"",H18/H17-1) -> 0.0097501187 | O18: =IF(OR(G18="",G17=""),"",G18/G17-1) -> 0.001447178 | P18: =IF(D18="","",D18/MAX($D$2:D18)-1) -> -0.090870696 | Q18: =IF(E18="","",E18/MAX($E$2:E18)-1) -> 0 | R18: =IF(H18="","",H18/MAX($H$2:H18)-1) -> -0.018522947 | S18: =IF(D18="","",100000*D18/$D$2) -> 107838.95 | T18: =IF(E18="","",100000*E18/$E$2) -> 127205.48 | U18: =IF(H18="","",100000*H18/$H$2) -> 118925.21 | V18: =IF(OR(S18="",G18="",$G$2=""),"",S18*$G$2/G18) -> 103631.36 | W18: =IF(OR(T18="",G18="",$G$2=""),"",T18*$G$2/G18) -> 122242.26 | X18: =IF(OR(U18="",G18="",$G$2=""),"",U18*$G$2/G18) -> 114285.07
A19: 42887 | B19: 64.4482 | C19: 1241.2 | D19: 80200 | E19: 9520.9 | F19: 2423.41 | G19: 69.5 | H19: =F19*B19 -> 156184.41 | I19: =IF(OR(B19="",B18=""),"",B19/B18-1) -> 0.00044551727 | J19: =IF(OR(C19="",C18=""),"",C19/C18-1) -> -0.02120512 | K19: =IF(OR(D19="",D18=""),"",D19/D18-1) -> -0.01953593 | L19: =IF(OR(E19="",E18=""),"",E19/E18-1) -> -0.010430038 | M19: =IF(OR(F19="",F18=""),"",F19/F18-1) -> 0.004813832 | N19: =IF(OR(H19="",H18=""),"",H19/H18-1) -> 0.0052614939 | O19: =IF(OR(G19="",G18=""),"",G19/G18-1) -> 0.0043352601 | P19: =IF(D19="","",D19/MAX($D$2:D19)-1) -> -0.10863138 | Q19: =IF(E19="","",E19/MAX($E$2:E19)-1) -> -0.010430038 | R19: =IF(H19="","",H19/MAX($H$2:H19)-1) -> -0.013358912 | S19: =IF(D19="","",100000*D19/$D$2) -> 105732.22 | T19: =IF(E19="","",100000*E19/$E$2) -> 125878.72 | U19: =IF(H19="","",100000*H19/$H$2) -> 119550.94 | V19: =IF(OR(S19="",G19="",$G$2=""),"",S19*$G$2/G19) -> 101168.23 | W19: =IF(OR(T19="",G19="",$G$2=""),"",T19*$G$2/G19) -> 120445.11 | X19: =IF(OR(U19="",G19="",$G$2=""),"",U19*$G$2/G19) -> 114390.46
... A130: 46266 | B130: 95.5124 | C130: 4157.34 | D130: 399043 | E130: 22620.45 | F130: 7651.54 | G130: 108.74 | H130: =F130*B130 -> 730816.95 | I130: =IF(OR(B130="",B129=""),"",B130/B129-1) -> 0.00071350515 | J130: =IF(OR(C130="",C129=""),"",C130/C129-1) -> -0.065539502 | K130: =IF(OR(D130="",D129=""),"",D130/D129-1) -> -0.057304512 | L130: =IF(OR(E130="",E129=""),"",E130/E129-1) -> -0.060628146 | M130: =IF(OR(F130="",F129=""),"",F130/F129-1) -> -0.0045016094 | N130: =IF(OR(H130="",H129=""),"",H130/H129-1) -> -0.0037913162 | O130: =IF(OR(G130="",G129=""),"",G130/G129-1) -> 0 | P130: =IF(D130="","",D130/MAX($D$2:D130)-1) -> -0.16985375 | Q130: =IF(E130="","",E130/MAX($E$2:E130)-1) -> -0.13672125 | R130: =IF(H130="","",H130/MAX($H$2:H130)-1) -> -0.0037913162 | S130: =IF(D130="","",100000*D130/$D$2) -> 526081.05 | T130: =IF(E130="","",100000*E130/$E$2) -> 299071.86 | U130: =IF(H130="","",100000*H130/$H$2) -> 559401.86 | V130: =IF(OR(S130="",G130="",$G$2=""),"",S130*$G$2/G130) -> 321725.12 | W130: =IF(OR(T130="",G130="",$G$2=""),"",T130*$G$2/G130) -> 182897.54 | X130: =IF(OR(U130="",G130="",$G$2=""),"",U130*$G$2/G130) -> 342102.48

Sheet Results
A1: RESULTS SUMMARY (populates after data is entered)
A3: Metric | B3: Gold INR (source) | C3: Nifty 50 TRI | D3: S&P 500 measured in INR | E3: Formula
A4: First available value | B4: ='Monthly Data'!D2 -> 75852 | C4: ='Monthly Data'!E2 -> 7563.55 | D4: ='Monthly Data'!H2 -> 130642.57 | E4: =_xlfn.FORMULATEXT(D4) -> ='Monthly Data'!H2
A5: Latest available value | B5: {=IFERROR(LOOKUP(2,1/('Monthly Data'!D:D<>""),'Monthly Data'!D:D),"")} -> 399043 | C5: =IFERROR(LOOKUP(2,1/('Monthly Data'!E:E<>""),'Monthly Data'!E:E),"") -> 22620.45 | D5: =IFERROR(LOOKUP(2,1/('Monthly Data'!H:H<>""),'Monthly Data'!H:H),"") -> 730816.95 | E5: =_xlfn.FORMULATEXT(D5) -> =IFERROR(LOOKUP(2,1/('Monthly Data'!H:H<>""),'Monthly Data'!H:H),"")
A6: Growth multiple | B6: =IFERROR(B5/B4,"") -> 5.2608105 | C6: =IFERROR(C5/C4,"") -> 2.9907186 | D6: =IFERROR(D5/D4,"") -> 5.5940186 | E6: =_xlfn.FORMULATEXT(D6) -> =IFERROR(D5/D4,"")
A7: Total return | B7: =IFERROR(B5/B4-1,"") -> 4.2608105 | C7: =IFERROR(C5/C4-1,"") -> 1.9907186 | D7: =IFERROR(D5/D4-1,"") -> 4.5940186 | E7: =_xlfn.FORMULATEXT(D7) -> =IFERROR(D5/D4-1,"")
A8: Annualised return (CAGR) | B8: =IFERROR((B5/B4)^(365.25/($B$13-$B$12))-1,"") -> 0.16841921 | C8: =IFERROR((C5/C4)^(365.25/($B$13-$B$12))-1,"") -> 0.1081638 | D8: =IFERROR((D5/D4)^(365.25/($B$13-$B$12))-1,"") -> 0.17516572 | E8: =_xlfn.FORMULATEXT(D8) -> =IFERROR((D5/D4)^(365.25/($B$13-$B$12))-1,"")
A9: Worst observed drawdown | B9: =IFERROR(MIN('Monthly Data'!P2:P132),"") -> -0.21075329 | C9: =IFERROR(MIN('Monthly Data'!Q2:Q132),"") -> -0.29343918 | D9: =IFERROR(MIN('Monthly Data'!R2:R132),"") -> -0.19921112 | E9: =_xlfn.FORMULATEXT(D9) -> =IFERROR(MIN('Monthly Data'!R2:R132),"")
A12: First Date | B12: ='Monthly Data'!A2 -> 42370
A13: Last Date | B13: ='Monthly Data'!A130 -> 46266
A15: The S&P 500 INR proxy has the highest calculated return in this sample, with gold close behind. Currency conversion is part of this result.
A16: Inflation matters: the CPI series rises from 66.50 to 108.74, meaning nominal gains overstate the increase in purchasing power.
A17: Nifty 50 TRI experienced the deepest monthly-observation drawdown of the three series, despite producing a positive long-term return.
A18: Gold has delivered substantial nominal growth in the supplied INR series, but the result is not the same as the realised return from buying physical gold or a gold fund.
A19: The results are historical, not predictive. They do not establish which asset will perform best in the future.
A22: 1. Historical investment performance | B22: Across the January 2016–September 2026 sample, the S&P 500 converted into INR recorded the highest calculated CAGR at 17.52%, followed closely by source INR gold at 16.84%. Nifty 50 TRI recorded a CAGR of 10.82%. On the supplied starting and ending values, the corresponding growth multiples were approximately 5.59×, 5.26× and 2.99×, respectively. | H22: Overall conclusion | I22: In this historical sample, the S&P 500 INR proxy and source INR gold outperformed Nifty 50 TRI on annualised nominal return, while Nifty 50 TRI experienced the largest observed drawdown. The comparison highlights the importance of currency effects, risk and inflation when evaluating investments from an Indian investor's perspective. It does not establish that gold or US equities will outperform Indian equities in the future.
A24: 2. Currency conversion matters | B24: The return experienced by an Indian investor in a US asset depends on both the asset's USD return and movements in USD/INR. Rupee depreciation can increase the INR value of US investments, while rupee appreciation can reduce it. The S&P 500 INR result is therefore a currency-adjusted proxy, not simply the S&P 500's US-market return.
H25: Limitations | I25: The findings depend on the quality, timing, units and consistency of the supplied monthly series. The S&P 500 conversion uses monthly-average USD/INR data and should be described as a proxy. The S&P index's total-return status and the CPI series must be verified. The analysis also excludes transaction costs, taxes, fund expenses, tracking error and other investor-specific costs.
A27: 3. Risk and drawdowns | B27: The supplied monthly series shows the deepest observed drawdown for Nifty 50 TRI at −29.34%, compared with −21.08% for source INR gold and −19.92% for the S&P 500 INR proxy. This suggests that, in this sample, Nifty experienced the largest peak-to-trough decline. Drawdown measures historical downside from a previous peak; it does not measure every aspect of investment risk.
A30: 4. Nominal returns versus purchasing power | B30: Nominal growth does not fully represent the improvement in purchasing power. The investment values should therefore be assessed alongside a consistently sourced CPI series. The inflation-adjusted scenario outputs are only reliable after the CPI calculation and inflation assumptions have been corrected and verified.
A33: 5. Scenario analysis | B33: Scenario Manager illustrates how future values change when assumptions about asset returns, exchange-rate depreciation and inflation change. These scenarios are hypothetical sensitivity tests, not predictions. Their purpose is to reveal which assumptions have the greatest influence on the result.

Sheet Scenario Analysis
D1: Scenario Summary
A2: Initial investment | B2: 100000 | F2: Current Values: | G2: Optimistic | H2: Best case | I2: Stress Case
A3: Investment horizon | B3: 10 | D3: Variables :
A4: Nifty annual return | B4: 0.1081638 | D4: Nifty annual return | F4: 0.1081638 | G4: 0.14 | H4: 0.1081638 | I4: 0.05
A5: S&P 500 annual USD return | B5: 0.13727373 | D5: S&P 500 annual USD return | F5: 0.13727373 | G5: 0.17 | H5: 0.13727373 | I5: 0.06
A6: Annual INR depreciation | B6: 0.033318274 | D6: Annual INR depreciation | F6: 0.033318274 | G6: 0.08 | H6: 0.033318274 | I6: 0.02
A7: Gold annual INR return | B7: 0.16841921 | D7: Gold annual INR return | F7: 0.16841921 | G7: 0.21 | H7: 0.16841921 | I7: 0.08
A8: Annual inflation | B8: 0.0038685738 | D8: Annual inflation | F8: 0.0038685738 | G8: 0.06 | H8: 0.0038685738 | I8: 0.0025
D9: Result Cells:
A10: Nominal and Inflation-Adjusted Future Values | B10: Value | D10: Nifty ending value | F10: 279279.84 | G10: 370722.13 | H10: 279279.84 | I10: 162889.46
A11: Nifty ending value | B11: =B2*(1+B4)^B3 -> 279279.84 | D11: S&P 500 ending value in INR | F11: 502332.36 | G11: 1037758.2 | H11: 502332.36 | I11: 218303.33
A12: S&P 500 ending value in INR | B12: =B2*((1+B5)*(1+B6))^B3 -> 502332.36 | D12: Gold ending value | F12: 474227.65 | G12: 672749.99 | H12: 474227.65 | I12: 215892.5
A13: Gold ending value | B13: =B2*(1+B7)^B3 -> 474227.65 | D13: Inflation-adjusted Nifty value | F13: 268702.06 | G13: 207009.3 | H13: 268702.06 | I13: 158872.66
A14: Inflation-adjusted Nifty value | B14: =B2*(1+B4)^B3/(1+B8)^B3 -> 268702.06 | D14: Inflation-adjusted S&P value | F14: 483306.43 | G14: 579478.76 | H14: 483306.43 | I14: 212920.05
A15: Inflation-adjusted S&P value | B15: =B2*((1+B5)*(1+B6))^B3/(1+B8)^B3 -> 483306.43 | D15: Inflation-adjusted Gold value | F15: 456266.18 | G15: 375660.08 | H15: 456266.18 | I15: 210568.66
A16: Inflation-adjusted Gold value | B16: =B2*(1+B7)^B3/(1+B8)^B3 -> 456266.18

Sheet Methods & Definitions
A1: Metric | B1: Definition / formula | C1: Interpretation caution
A2: Monthly return | B2: Current value / previous value - 1 | C2: Ensure the observations represent comparable periods.
A3: Cumulative return | B3: Ending value / beginning value - 1 | C3: Does not account for contributions, taxes or fees.
A4: CAGR | B4: (Ending value / beginning value)^(12 / number of monthly observations) - 1 | C4: Annualised compound growth; use elapsed months carefully.
A5: USD asset converted to INR | B5: USD asset index × USD/INR | C5: The USD/INR quote is INR per USD, so multiplying converts USD value to INR.
A6: Gold INR from USD | B6: Gold USD/oz × USD/INR | C6: This yields INR per troy ounce. Divide by 31.1034768 for INR per gram.
A7: Drawdown | B7: Current value / running peak - 1 | C7: Negative values show declines from prior peaks.
A8: Real value | B8: Nominal value × base-period CPI / current CPI | C8: Use a consistent CPI series and base.
A9: Currency effect | B9: (1 + USD asset return) × (1 + FX return) - 1 | C9: Exact multiplicative decomposition, before costs.
A10: Total-return index | B10: Includes reinvested dividends/distributions according to provider methodology | C10: Confirm index methodology and corporate-action treatment.
A11: SIP comparison | B11: Invest the same cash amount on each monthly date using actual monthly price/index | C11: A fair SIP simulation requires actual cash-flow timing and consistent dates.

Sheet Scenario Summary 
B2: Scenario Summary
D3: Current Values: | E3: Optimistic | F3: Best case | G3: Stress Case
E4: Created by Nandhakumar T on 10-10-2026 Modified by Nandhakumar T on 10-10-2026 | F4: Created by Nandhakumar T on 10-10-2026 Modified by Nandhakumar T on 10-10-2026 | G4: Created by Nandhakumar T on 10-10-2026 Modified by Nandhakumar T on 10-10-2026
B5: Changing Cells:
C6: $B$4 | D6: 0.1081638 | E6: 0.14 | F6: 0.1081638 | G6: 0.05
C7: $B$5 | D7: 0.13727373 | E7: 0.17 | F7: 0.13727373 | G7: 0.06
C8: $B$6 | D8: 0.033318274 | E8: 0.08 | F8: 0.033318274 | G8: 0.02
C9: $B$7 | D9: 0.16841921 | E9: 0.21 | F9: 0.16841921 | G9: 0.08
C10: $B$8 | D10: 0.0038685738 | E10: 0.06 | F10: 0.0038685738 | G10: 0.0025
B11: Result Cells:
C12: $B$11 | D12: 279279.84 | E12: 370722.13 | F12: 279279.84 | G12: 162889.46
C13: $B$12 | D13: 502332.36 | E13: 1037758.2 | F13: 502332.36 | G13: 218303.33
C14: $B$13 | D14: 474227.65 | E14: 672749.99 | F14: 474227.65 | G14: 215892.5
C15: $B$14 | D15: 268702.06 | E15: 207009.3 | F15: 268702.06 | G15: 158872.66
C16: $B$15 | D16: 483306.43 | E16: 579478.76 | F16: 483306.43 | G16: 212920.05
C17: $B$16 | D17: 456266.18 | E17: 375660.08 | F17: 456266.18 | G17: 210568.66
B18: Notes: Current Values column represents values of changing cells at
B19: time Scenario Summary Report was created. Changing cells for each
B20: scenario are highlighted in gray.
